try{
    hello();
}catch(error){
    console.log(error);//Presenta el error devuelto.
}

/////////////////////// Nuevo ejemplo de ejecuci√≥n

try{
    anotherFn();
}catch(error){
    console.log('Esto es un error!');//Presenta error personalizado.
}
